Workbook

Sheet Sheet7
A1: شماره فني | B1: شرح قطعه | C1: خانواده قطعات
A2: IK01403980 | B2: NBCM DENA | C2: NOD
A3: IK01596980 | B3: NBCM 207 | C3: NOD
A4: IK01597080 | B4: NBCM 207 | C4: NOD
A5: IK01262380 | B5: NBCM TARA | C5: NOD
A6: IK01843080 | B6: NBCM TARA SAL | C6: NOD
A7: IK02628880 | B7: NBCM DENA SBR | C7: NOD
A8: IK01750880 | B8: NBCM SOREN | C8: NOD
A9: YG20240320 | B9: SBM 207 | C9: NOD
A10: IK01298280 | B10: SBM ARISUN | C10: NOD
A11: IK01403780 | B11: NBCM SOREN | C11: NOD
A12: IK00019080 | B12: جلو آمپر دنا معمولی | C12: جلو آمپر
... A37: YG20238404 | B37: جلو آمپر PARS کهربایی | C37: جلو آمپر
A38: 72320818 | B38: جلو آمپرPU1 | C38: جلو آمپر
A39: YG20238399 | B39: جلو آمپر PARS 14" SA | C39: جلو آمپر
A40: YG20238401 | B40: جلو آمپر PARS 15" SA | C40: جلو آمپر
A41: IK016268PB | B41: کلید شیشه بالابر جلو چپ سورن | C41: کلید شیشه بالابر
A42: IK016271PB | B42: کلید شیشه بالابر عقب راست سورن | C42: کلید شیشه بالابر
A43: IK016269PB | B43: کلید شیشه بالابر جلو راست سورن | C43: کلید شیشه بالابر
A44: IK016270PB | B44: کلید شیشه بالابر عقب چپ سورن | C44: کلید شیشه بالابر
A45: IK014085DG | B45: کلید شیشه بالابر جلو چپ دنا | C45: کلید شیشه بالابر
A46: IK003290DG | B46: کلید شیشه بالابرعقب دنا | C46: کلید شیشه بالابر
A47: IK003294DG | B47: کلید شیشه بالابرجلو راست دنا | C47: کلید شیشه بالابر
A48: IK00473280 | B48: MFD RUNNA | C48: MFD
A49: IK02625280 | B49: جلو آمپر دنا اتوماتیک SBR | C49: جلو آمپر
A50: IK02627480 | B50: NBCM TARA SAL SBR | C50: NOD
... A61: IK02623880 | B61: جلو آمپر207 اتوماتیک85 گانه SBR | C61: جلو آمپر

Sheet لیست قطعات برگشتی1403 (2)
A1: تعداد اخطار کیفی | B1: سريال اخطار | C1: تاريخ تاييد | D1: ماهیانه | E1: ماه | F1: سال | G1: محصولات | H1: شرح قطعه | I1: ایراد اعلام شده مشتری | J1: شرح ایراد | K1: تستر | L1: تاریخ تست | M1: تست خودرویی | N1: تاریخ تست خودرویی | O1: تست پیشنهادی | P1: تاریخ تست پیشنهادی | Q1: بررسی اول | R1: بررسی دوم | S1: بررسی سوم | T1: ریشه ایراد | U1: دلیل ایجاد ایراد | V1: تعداد قطعات معيوب | W1: شماره فني | X1: بارکد محصول | Y1: تاریخ تحویل قطعه | Z1: تحویل گیرنده | AA1: 6M | AB1: تجهیزات | AC1: کد اپراتور | AD1: وضعیت | AE1: اقدام تعریف شده | AF1: مدارک
A2: 1 | B2: 194290 | C2: 1403/01/16 | D2: =MID(Table22[[#This Row],[تاريخ تاييد]],1,7) -> 1403/01 | E2: =MID(Table22[[#This Row],[تاريخ تاييد]],6,2) -> 01 | F2: 1403 | G2: =VLOOKUP(Table22[[#This Row],[شماره فني]],Sheet7!A:C,3,0) -> NOD | H2: =VLOOKUP(Table22[[#This Row],[شماره فني]],Sheet7!A:B,2,0) -> NBCM DENA | I2: ايراد عملكردي nbcm (ليبل تكراري قطعه در تاريخ 1402/12/22 مونتاژ شده) رويت شد | J2: ایراد در لیبل | K2: - | L2: - | M2: - | N2: - | O2: - | P2: - | Q2: - | R2: - | S2: اشتباه اپراتور خط مشتری | T2: اشتباه اپراتور خط مشتری | U2: اشتباه اپراتور خط مشتری | V2: 1 | W2: IK01403980 | X2: - | Y2: 1403/02/26 | Z2: کاظمی پور | AA2: روش | AB2: - | AC2: - | AD2: بسته شده | AE2: - | AF2: -
A3: 1 | B3: 194407 | C3: 1403/01/19 | D3: =MID(Table22[[#This Row],[تاريخ تاييد]],1,7) -> 1403/01 | E3: =MID(Table22[[#This Row],[تاريخ تاييد]],6,2) -> 01 | F3: 1403 | G3: =VLOOKUP(Table22[[#This Row],[شماره فني]],Sheet7!A:C,3,0) -> جلو آمپر | H3: =VLOOKUP(Table22[[#This Row],[شماره فني]],Sheet7!A:B,2,0) -> جلو آمپرSOREN TC 85 گانه | I3: ايراد عدم جذب پشت امپر كه طبق بررسي هاي انجام گرفته ايراد فقط در سورس سازه پويش رويت مي گردد به طوريكه در پشت امپر كروز ايراد عدم جذب مشاهده نمي شود كه ايراد به رويت نماينده ساپكو اقاي كثيري رسيد(شكيب) | J3: ایراد ظاهری | K3: - | L3: - | M3: - | N3: - | O3: - | P3: - | Q3: ایراد ظاهری بود رویت شد | R3: - | S3: بزل | T3: ظاهری | U3: ایراد در مواد اولیه | V3: 50 | W3: IK01033880 | X3: - | Y3: - | Z3: - | AA3: مواد اولیه | AB3: - | AC3: - | AD3: بسته شده | AE3: - | AF3: -
A4: 1 | B4: 194427 | C4: 1403/01/19 | D4: =MID(Table22[[#This Row],[تاريخ تاييد]],1,7) -> 1403/01 | E4: =MID(Table22[[#This Row],[تاريخ تاييد]],6,2) -> 01 | F4: 1403 | G4: =VLOOKUP(Table22[[#This Row],[شماره فني]],Sheet7!A:C,3,0) -> جلو آمپر | H4: =VLOOKUP(Table22[[#This Row],[شماره فني]],Sheet7!A:B,2,0) -> جلو آمپر دنا اتوماتیک | I4: عطف به اسلايد2 فايل پيوست نتيجه گزارش دريافت شده از تستهاي دوره اي قطعه در اتيراك،عملكرد قطعه در بررسي پس از تست شوك حرارتي صحيح نميباشد. | J4: عدم عملكرد كامل | K4: - | L4: - | M4: - | N4: - | O4: - | P4: - | Q4: با توجه به اینکه قطعه دریافت نگردیده و ایراد مشابه در اخطار کیفی پیشین وجود داشته است،پاسخ حاضر بر اساس اقدامات قبلی ارائه شده است. | R4: - | S4: - | T4: عدم دریافت قطعه | U4: پاسخ با ایراد مشابه(عدم دریافت قطعه) | V4: 1 | W4: IK00929380 | X4: - | Y4: - | Z4: - | AA4: نامشخص | AB4: - | AC4: - | AD4: بسته شده | AE4: - | AF4: -
A5: 1 | B5: 194486 | C5: 1403/01/21 | D5: =MID(Table22[[#This Row],[تاريخ تاييد]],1,7) -> 1403/01 | E5: =MID(Table22[[#This Row],[تاريخ تاييد]],6,2) -> 01 | F5: 1403 | G5: =VLOOKUP(Table22[[#This Row],[شماره فني]],Sheet7!A:C,3,0) -> NOD | H5: =VLOOKUP(Table22[[#This Row],[شماره فني]],Sheet7!A:B,2,0) -> NBCM 207 | I5: ايراد عملكرد نادرست NBCM( مغايرت كانكتورنصب اشتباه)يك نمونه رويت شد | J5: کانکتور | K5: - | L5: - | M5: - | N5: - | O5: - | P5: - | Q5: با توجه به اینکه قطعه دریافت نگردیده و ایراد مشابه در اخطار کیفی پیشین وجود داشته است،پاسخ حاضر بر اساس اقدامات قبلی ارائه شده است. | R5: - | S5: - | T5: عدم دریافت قطعه | U5: پاسخ با ایراد مشابه(عدم دریافت قطعه) | V5: 1 | W5: IK01596980 | X5: - | Y5: - | Z5: - | AA5: نامشخص | AB5: - | AC5: - | AD5: بسته شده | AE5: - | AF5: -
A6: 1 | B6: 194549 | C6: 1403/01/21 | D6: =MID(Table22[[#This Row],[تاريخ تاييد]],1,7) -> 1403/01 | E6: =MID(Table22[[#This Row],[تاريخ تاييد]],6,2) -> 01 | F6: 1403 | G6: =VLOOKUP(Table22[[#This Row],[شماره فني]],Sheet7!A:C,3,0) -> جلو آمپر | H6: =VLOOKUP(Table22[[#This Row],[شماره فني]],Sheet7!A:B,2,0) -> جلو آمپر دنا اتوماتیک | I6: طي بررسي بعمل آمده ايراد عملكرد آمپر صفحه نمايشگر يك نمونه رويت گرديد | J6: LCD | K6: NOK | L6: 1403/04/11 | M6: - | N6: - | O6: - | P6: - | Q6: LCD معیوب | R6: تحویل مهندس رحمانی پور | S6: LCD | T6: قطعه معیوب | U6: ایراد در مواد اولیه | V6: 1 | W6: IK00929380 | X6: RJAD2F10160269 | Y6: 1403/04/11 | Z6: کاظمی پور | AA6: مواد اولیه | AB6: - | AC6: - | AD6: بسته شده | AE6: - | AF6: -
A7: 1 | B7: 194583 | C7: 1403/01/23 | D7: =MID(Table22[[#This Row],[تاريخ تاييد]],1,7) -> 1403/01 | E7: =MID(Table22[[#This Row],[تاريخ تاييد]],6,2) -> 01 | F7: 1403 | G7: =VLOOKUP(Table22[[#This Row],[شماره فني]],Sheet7!A:C,3,0) -> NOD | H7: =VLOOKUP(Table22[[#This Row],[شماره فني]],Sheet7!A:B,2,0) -> NBCM DENA | I7: ايرادعدم عملكرد NBCM( عدم عملكرد كامل)يك نمونه رويت شد | J7: عدم عملكرد ادوات برقي خودرو | K7: - | L7: - | M7: - | N7: - | O7: - | P7: - | Q7: با توجه به اینکه قطعه دریافت نگردیده و ایراد مشابه در اخطار کیفی پیشین وجود داشته است،پاسخ حاضر بر اساس اقدامات قبلی ارائه شده است. | R7: - | S7: - | T7: عدم دریافت قطعه | U7: پاسخ با ایراد مشابه(عدم دریافت قطعه) | V7: 1 | W7: IK01403980 | X7: - | Y7: - | Z7: - | AA7: نامشخص | AB7: - | AC7: - | AD7: بسته شده | AE7: - | AF7: -
A8: 1 | B8: 194584 | C8: 1403/01/23 | D8: =MID(Table22[[#This Row],[تاريخ تاييد]],1,7) -> 1403/01 | E8: =MID(Table22[[#This Row],[تاريخ تاييد]],6,2) -> 01 | F8: 1403 | G8: =VLOOKUP(Table22[[#This Row],[شماره فني]],Sheet7!A:C,3,0) -> جلو آمپر | H8: =VLOOKUP(Table22[[#This Row],[شماره فني]],Sheet7!A:B,2,0) -> جلو آمپر207 معمولی85 گانه | I8: ايرادليبل تكراري آمپرخودرو207يك نمونه رويت شد | J8: ایراد در لیبل | K8: - | L8: - | M8: - | N8: - | O8: - | P8: - | Q8: با توجه به اینکه قطعه دریافت نگردیده و ایراد مشابه در اخطار کیفی پیشین وجود داشته است،پاسخ حاضر بر اساس اقدامات قبلی ارائه شده است. | R8: - | S8: - | T8: عدم دریافت قطعه | U8: پاسخ با ایراد مشابه(عدم دریافت قطعه) | V8: 1 | W8: IK01033680 | X8: - | Y8: - | Z8: - | AA8: نامشخص | AB8: - | AC8: - | AD8: بسته شده | AE8: - | AF8: -
A9: 1 | B9: 194773 | C9: 1403/01/27 | D9: =MID(Table22[[#This Row],[تاريخ تاييد]],1,7) -> 1403/01 | E9: =MID(Table22[[#This Row],[تاريخ تاييد]],6,2) -> 01 | F9: 1403 | G9: =VLOOKUP(Table22[[#This Row],[شماره فني]],Sheet7!A:C,3,0) -> NOD | H9: =VLOOKUP(Table22[[#This Row],[شماره فني]],Sheet7!A:B,2,0) -> NBCM 207 | I9: ايرادعدم عملكرد NBCM( عدم عملكرد كامل اتصالي ادوات برقي )يك نمونه رويت شد | J9: عدم عملكرد ادوات برقي خودرو | K9: NOK | L9: 1403/02/26 | M9: - | N9: - | O9: - | P9: - | Q9: آثار فلکس بر روی pcb | R9: اتصالی اهمی | S9: برد | T9: اتصالی | U9: عدم عملکرد صحیح صفحه گرمایشی | V9: 1 | W9: IK01596980 | X9: RU827F10162125 | Y9: 1403/02/26 | Z9: کاظمی پور | AA9: تجهیزات | AB9: وان قلع | AC9: - | AD9: بسته شده | AE9: - | AF9: -
A10: 1 | B10: 194942 | C10: 1403/02/01 | D10: =MID(Table22[[#This Row],[تاريخ تاييد]],1,7) -> 1403/02 | E10: =MID(Table22[[#This Row],[تاريخ تاييد]],6,2) -> 02 | F10: 1403 | G10: =VLOOKUP(Table22[[#This Row],[شماره فني]],Sheet7!A:C,3,0) -> جلو آمپر | H10: =VLOOKUP(Table22[[#This Row],[شماره فني]],Sheet7!A:B,2,0) -> جلو آمپر دنا اتوماتیک | I10: ايرادعدم عملكردآمپرخودرو دنا(صفحه نمايشگر)يك نمونه رويت شد | J10: LCD | K10: OK | L10: 1403/02/26 | M10: NOK | N10: 1403/03/13 | O10: - | P10: - | Q10: LCD در تست خودرویی خاموش | R10: تحویل مهندس لهراسبی | S10: LCD | T10: قطعه معیوب | U10: ایراد در مواد اولیه | V10: 1 | W10: IK00929380 | X10: RJAD2F10270105 | Y10: 1403/02/26 | Z10: کاظمی پور | AA10: مواد اولیه | AB10: - | AC10: - | AD10: بسته شده | AE10: - | AF10: -
A11: 1 | B11: 194984 | C11: 1403/02/01 | D11: =MID(Table22[[#This Row],[تاريخ تاييد]],1,7) -> 1403/02 | E11: =MID(Table22[[#This Row],[تاريخ تاييد]],6,2) -> 02 | F11: 1403 | G11: =VLOOKUP(Table22[[#This Row],[شماره فني]],Sheet7!A:C,3,0) -> NOD | H11: =VLOOKUP(Table22[[#This Row],[شماره فني]],Sheet7!A:B,2,0) -> NBCM 207 | I11: ايراد عملكردي NBCM( عدم عملكرد سايد لمپ )يك نمونه رويت شد | J11: عدم عملكرد ادوات برقي خودرو | K11: NOK | L11: 1403/02/26 | M11: - | N11: - | O11: - | P11: - | Q11: - | R11: کمبود قلع پد تغذیه BTS | S11: IC BTS | T11: کمبود قلع | U11: مسدود بودن بخشی از سوراخ استنسیل و کامل نشدن مرحله چاپ قلع | V11: 1 | W11: IK01596980 | X11: RU827F10282114 | Y11: 1403/02/26 | Z11: کاظمی پور | AA11: تجهیزات | AB11: SCREEN PRINTER | AC11: - | AD11: بسته شده | AE11: - | AF11: -
A12: 1 | B12: 194985 | C12: 1403/02/01 | D12: =MID(Table22[[#This Row],[تاريخ تاييد]],1,7) -> 1403/02 | E12: =MID(Table22[[#This Row],[تاريخ تاييد]],6,2) -> 02 | F12: 1403 | G12: =VLOOKUP(Table22[[#This Row],[شماره فني]],Sheet7!A:C,3,0) -> جلو آمپر | H12: =VLOOKUP(Table22[[#This Row],[شماره فني]],Sheet7!A:B,2,0) -> جلو آمپر207 اتوماتیک85 گانه | I12: ايرادعدم عملكردآمپرخودرو207(عدم نمايش دماسنج)يك نمونه رويت شد | J12: عدم عملكرد ادوات برقي خودرو | K12: NOK | L12: 1403/02/26 | M12: - | N12: - | O12: - | P12: - | Q12: جدا شدن ترانزیستور | R12: آثار ضربه بر روی ترانزیستور مشهود است | S12: ترانزیستور | T12: کنده شدن قطعه | U12: بر اثر جابجایی | V12: 1 | W12: IK01917980 | X12: RJA24F10140015 | Y12: 1403/02/26 | Z12: کاظمی پور | AA12: روش | AB12: - | AC12: - | AD12: بسته شده | AE12: - | AF12: -
A13: 1 | B13: 194986 | C13: 1403/02/01 | D13: =MID(Table22[[#This Row],[تاريخ تاييد]],1,7) -> 1403/02 | E13: =MID(Table22[[#This Row],[تاريخ تاييد]],6,2) -> 02 | F13: 1403 | G13: =VLOOKUP(Table22[[#This Row],[شماره فني]],Sheet7!A:C,3,0) -> NOD | H13: =VLOOKUP(Table22[[#This Row],[شماره فني]],Sheet7!A:B,2,0) -> NBCM DENA | I13: ايراد مغايرت ليبل رديابي NBCM( ناخوانا بودن كه مربوط به توليد204 روز ) رويت شد | J13: ایراد در لیبل | K13: - | L13: - | M13: - | N13: - | O13: - | P13: - | Q13: - | R13: - | S13: محصول | T13: چاپ نامناسب لیبل | U13: ایراد در ریبون پرینتر | V13: 3 | W13: IK01403980 | X13: - | Y13: - | Z13: - | AA13: تجهیزات | AB13: پرینتر | AC13: - | AD13: بسته شده | AE13: - | AF13: -
... A123: 1 | B123: 203284 | C123: 1403/07/26 | D123: =MID(Table22[[#This Row],[تاريخ تاييد]],1,7) -> 1403/07 | E123: =MID(Table22[[#This Row],[تاريخ تاييد]],6,2) -> 07 | F123: 1403 | G123: =VLOOKUP(Table22[[#This Row],[شماره فني]],Sheet7!A:C,3,0) -> جلو آمپر | H123: =VLOOKUP(Table22[[#This Row],[شماره فني]],Sheet7!A:B,2,0) -> جلو آمپر دنا ST | I123: ايراد عملكردجلوآمپر(قطع و وصل پشت آمپر ) رويت شد. | J123: صداي اضافه و قطع و وصل پشت آمپر | K123: OK | L123: 1403/08/18 | M123: - | N123: - | O123: - | P123: - | Q123: شکسته بودن خازن ورودی رگلاتور | R123: خازن بر اثر جایگذاری نامناسب برد و یا جابجایی شکسته | S123: خازن | T123: قطعه شکسته | U123: بر اثر جابجایی | V123: 1 | W123: IK00843780 | X123: - | Y123: 1403/08/13 | Z123: کاظمی پور | AA123: روش | AB123: - | AC123: - | AD123: بسته شده | AE123: - | AF123: -
A124: 1 | B124: 203380 | C124: 1403/07/28 | D124: =MID(Table22[[#This Row],[تاريخ تاييد]],1,7) -> 1403/07 | E124: =MID(Table22[[#This Row],[تاريخ تاييد]],6,2) -> 07 | F124: =LEFT(Table22[[#This Row],[تاريخ تاييد]],4) -> 1403 | G124: =VLOOKUP(Table22[[#This Row],[شماره فني]],Sheet7!A:C,3,0) -> جلو آمپر | H124: =VLOOKUP(Table22[[#This Row],[شماره فني]],Sheet7!A:B,2,0) -> جلو آمپر207 معمولی85 گانه | I124: ايراد عملكردجلوآمپر(عدم عملكرد كامل ) رويت شد. | J124: عدم عملكرد كامل | K124: NOK | L124: 1403/08/18 | M124: - | N124: - | O124: - | P124: - | Q124: باتوجه به بررسی کارگروه ایراد در مقدار خازن کریستال میباشد که از 22پیکو به 10 پیکو کاهش یافت | R124: با شوک حرارتی قطعه Okشد | S124: کریستال | T124: قطعه معیوب | U124: ایراد در مواد اولیه | V124: 1 | W124: IK01033680 | X124: - | Y124: 1403/08/13 | Z124: کاظمی پور | AA124: مواد اولیه | AB124: - | AC124: - | AD124: بسته شده | AE124: مقدار خازن کریستال از 22پیکو به 10 پیکو کاهش یافت | AF124: -
A125: 1 | B125: 203385 | C125: 1403/07/28 | D125: =MID(Table22[[#This Row],[تاريخ تاييد]],1,7) -> 1403/07 | E125: =MID(Table22[[#This Row],[تاريخ تاييد]],6,2) -> 07 | F125: =LEFT(Table22[[#This Row],[تاريخ تاييد]],4) -> 1403 | G125: =VLOOKUP(Table22[[#This Row],[شماره فني]],Sheet7!A:C,3,0) -> NOD | H125: =VLOOKUP(Table22[[#This Row],[شماره فني]],Sheet7!A:B,2,0) -> NBCM TARA SAL | I125: اختلال عملكردي نودهاي مرتبط با NBCM طبق گزارش پسويت | J125: ایتراک | K125: - | L125: - | M125: - | N125: - | O125: - | P125: - | Q125: - | R125: - | S125: - | T125: عدم دریافت قطعه | U125: عدم دریافت قطعه | V125: 1 | W125: IK01843080 | X125: - | Y125: - | Z125: - | AA125: نامشخص | AB125: - | AC125: - | AD125: عدم دریافت قطعه | AE125: - | AF125: -
A126: 1 | B126: 203468 | C126: 1403/07/29 | D126: =MID(Table22[[#This Row],[تاريخ تاييد]],1,7) -> 1403/07 | E126: =MID(Table22[[#This Row],[تاريخ تاييد]],6,2) -> 07 | F126: =LEFT(Table22[[#This Row],[تاريخ تاييد]],4) -> 1403 | G126: =VLOOKUP(Table22[[#This Row],[شماره فني]],Sheet7!A:C,3,0) -> کلید شیشه بالابر | H126: =VLOOKUP(Table22[[#This Row],[شماره فني]],Sheet7!A:B,2,0) -> کلید شیشه بالابر عقب چپ سورن | I126: پليسه گيري نامطلوب كليد شيشه بالابر*****طرقي | J126: ایراد ظاهری | K126: - | L126: - | M126: - | N126: - | O126: - | P126: - | Q126: با توجه به اینکه قطعه دریافت نگردیده و ایراد مشابه در اخطار کیفی پیشین وجود داشته است،پاسخ حاضر بر اساس اقدامات قبلی ارائه شده است. | R126: - | S126: - | T126: عدم دریافت قطعه | U126: پاسخ با ایراد مشابه(عدم دریافت قطعه) | V126: 5 | W126: IK016270PB | X126: - | Y126: - | Z126: - | AA126: نامشخص | AB126: - | AC126: - | AD126: بسته شده | AE126: - | AF126: -
A127: 1 | B127: 203534 | C127: 1403/07/30 | D127: =MID(Table22[[#This Row],[تاريخ تاييد]],1,7) -> 1403/07 | E127: =MID(Table22[[#This Row],[تاريخ تاييد]],6,2) -> 07 | F127: =LEFT(Table22[[#This Row],[تاريخ تاييد]],4) -> 1403 | G127: =VLOOKUP(Table22[[#This Row],[شماره فني]],Sheet7!A:C,3,0) -> NOD | H127: =VLOOKUP(Table22[[#This Row],[شماره فني]],Sheet7!A:B,2,0) -> NBCM DENA | I127: ايراد عملكرد NBCM ( روشن نشدن خودرو استارت عملكرد ندارد) 2 مورد رويت شد | J127: روشن نشدن خودرو | K127: NOK | L127: 1403/08/13 | M127: - | N127: - | O127: - | P127: - | Q127: قطعه دیود معیوب | R127: قطعه مورد تایید نبوده و در محصول استفاده گردیده | S127: دیود | T127: قطعه معیوب | U127: ایراد در مواد اولیه | V127: 2 | W127: IK01403980 | X127: - | Y127: 1403/08/13 | Z127: کاظمی پور | AA127: مواد اولیه | AB127: - | AC127: - | AD127: بسته شده | AE127: - | AF127: -
A128: 1 | B128: 203553 | C128: 1403/07/30 | D128: =MID(Table22[[#This Row],[تاريخ تاييد]],1,7) -> 1403/07 | E128: =MID(Table22[[#This Row],[تاريخ تاييد]],6,2) -> 07 | F128: =LEFT(Table22[[#This Row],[تاريخ تاييد]],4) -> 1403 | G128: =VLOOKUP(Table22[[#This Row],[شماره فني]],Sheet7!A:C,3,0) -> کلید شیشه بالابر | H128: =VLOOKUP(Table22[[#This Row],[شماره فني]],Sheet7!A:B,2,0) -> کلید شیشه بالابر جلو چپ دنا | I128: عدم عملكرد كليد آينه تاشو در مجموعه كليد شيشه بالابر جلو چپ - خاكستري تيره- خودرو دنا؛ مرتبط با شركت سازه پويش | J128: عدم عملكرد ادوات برقي خودرو | K128: NOK | L128: 1403/08/13 | M128: - | N128: - | O128: - | P128: - | Q128: عدم اتصال صحيح پايه ic | R128: عدم اتصال صحیح پایه(IC) | S128: IC | T128: عدم اتصال مناسب | U128: استفاده از استنسيل شركت فراكلون | V128: 1 | W128: IK014085DG | X128: - | Y128: 1403/08/09 | Z128: کاظمی پور | AA128: تجهیزات | AB128: SCREEN PRINTER | AC128: - | AD128: بسته شده | AE128: - | AF128: -
A129: 1 | B129: 203619 | C129: 1403/08/01 | D129: =MID(Table22[[#This Row],[تاريخ تاييد]],1,7) -> 1403/08 | E129: =MID(Table22[[#This Row],[تاريخ تاييد]],6,2) -> 08 | F129: =LEFT(Table22[[#This Row],[تاريخ تاييد]],4) -> 1403 | G129: =VLOOKUP(Table22[[#This Row],[شماره فني]],Sheet7!A:C,3,0) -> کلید شیشه بالابر | H129: =VLOOKUP(Table22[[#This Row],[شماره فني]],Sheet7!A:B,2,0) -> کلید شیشه بالابر عقب راست سورن | I129: وجود پليسه و پليسه گيري نامناسب قاب كليد شيشه بالابر عقب راست | J129: ایراد ظاهری | K129: - | L129: - | M129: - | N129: - | O129: - | P129: - | Q129: با توجه به اینکه قطعه دریافت نگردیده و ایراد مشابه در اخطار کیفی پیشین وجود داشته است،پاسخ حاضر بر اساس اقدامات قبلی ارائه شده است. | R129: - | S129: - | T129: عدم دریافت قطعه | U129: پاسخ با ایراد مشابه(عدم دریافت قطعه) | V129: 3 | W129: IK016271PB | X129: - | Y129: - | Z129: - | AA129: نامشخص | AB129: - | AC129: - | AD129: بسته شده | AE129: - | AF129: -
A130: 1 | B130: 203749 | C130: 1403/08/05 | D130: =MID(Table22[[#This Row],[تاريخ تاييد]],1,7) -> 1403/08 | E130: =MID(Table22[[#This Row],[تاريخ تاييد]],6,2) -> 08 | F130: =LEFT(Table22[[#This Row],[تاريخ تاييد]],4) -> 1403 | G130: =VLOOKUP(Table22[[#This Row],[شماره فني]],Sheet7!A:C,3,0) -> جلو آمپر | H130: =VLOOKUP(Table22[[#This Row],[شماره فني]],Sheet7!A:B,2,0) -> جلو آمپر تارا اتوماتیک | I130: ايراد ظاهري جلوآمپر(كج بودن عقربه دور موتور ) رويت شد | J130: عقربه | K130: NOK | L130: 1403/09/07 | M130: - | N130: - | O130: - | P130: - | Q130: در زمان مونتاژ عقربه به دلیل عدم جایگیری صحیح در گیج با فشار لودسل عقربه کج و توسط بازرس دیده نشده | R130: انحنا در عقربه | S130: عقربه | T130: قطعه معیوب | U130: عدم جایگذاری مناسب عقربه در فیکسچر | V130: 1 | W130: IK01348180 | X130: - | Y130: 1403/09/07 | Z130: کاظمی پور | AA130: اپراتور | AB130: - | AC130: تندرو،زندی | AD130: بسته شده | AE130: - | AF130: -
A131: 1 | B131: 203785 | C131: 1403/08/05 | D131: =MID(Table22[[#This Row],[تاريخ تاييد]],1,7) -> 1403/08 | E131: =MID(Table22[[#This Row],[تاريخ تاييد]],6,2) -> 08 | F131: =LEFT(Table22[[#This Row],[تاريخ تاييد]],4) -> 1403 | G131: =VLOOKUP(Table22[[#This Row],[شماره فني]],Sheet7!A:C,3,0) -> کلید شیشه بالابر | H131: =VLOOKUP(Table22[[#This Row],[شماره فني]],Sheet7!A:B,2,0) -> کلید شیشه بالابر جلو چپ سورن | I131: ايراد عدم عملكرد كليد ها طبق بررسي مشخص گرديد ايراد مربوط به درفتگي خار پنل كليد بالابر كه ايراد به رويت نماينده سازنده اقاي راوندي رسيد | J131: ایراد ظاهری | K131: - | L131: - | M131: - | N131: - | O131: - | P131: - | Q131: کم بودن گوشت خار مجموعه کلید | R131: - | S131: قاب | T131: چفت نشدن خار | U131: ایراد در مواد اولیه | V131: 5 | W131: IK016268PB | X131: - | Y131: 1403/09/07 | Z131: کاظمی پور | AA131: مواد اولیه | AB131: - | AC131: - | AD131: بسته شده | AE131: - | AF131: -
A132: 1 | B132: 203803 | C132: 1403/08/06 | D132: =MID(Table22[[#This Row],[تاريخ تاييد]],1,7) -> 1403/08 | E132: =MID(Table22[[#This Row],[تاريخ تاييد]],6,2) -> 08 | F132: =LEFT(Table22[[#This Row],[تاريخ تاييد]],4) -> 1403 | G132: =VLOOKUP(Table22[[#This Row],[شماره فني]],Sheet7!A:C,3,0) -> NOD | H132: =VLOOKUP(Table22[[#This Row],[شماره فني]],Sheet7!A:B,2,0) -> NBCM TARA SAL | I132: ايراد عملكرد NBCM (خطاي مجازي .عدم پيكربنديNot OK) 1 مورد رويت شد | J132: خطاي مجازي | K132: - | L132: - | M132: - | N132: - | O132: - | P132: - | Q132: با توجه به اینکه قطعه دریافت نگردیده و ایراد مشابه در اخطار کیفی پیشین وجود داشته است،پاسخ حاضر بر اساس اقدامات قبلی ارائه شده است. | R132: - | S132: - | T132: عدم دریافت قطعه | U132: پاسخ با ایراد مشابه(عدم دریافت قطعه) | V132: 1 | W132: IK01843080 | X132: - | Y132: - | Z132: - | AA132: نامشخص | AB132: - | AC132: - | AD132: بسته شده | AE132: - | AF132: -
A133: 1 | B133: 203821 | C133: 1403/08/06 | D133: =MID(Table22[[#This Row],[تاريخ تاييد]],1,7) -> 1403/08 | E133: =MID(Table22[[#This Row],[تاريخ تاييد]],6,2) -> 08 | F133: =LEFT(Table22[[#This Row],[تاريخ تاييد]],4) -> 1403 | G133: =VLOOKUP(Table22[[#This Row],[شماره فني]],Sheet7!A:C,3,0) -> NOD | H133: =VLOOKUP(Table22[[#This Row],[شماره فني]],Sheet7!A:B,2,0) -> NBCM DENA | I133: ايراد عملكرد NBCM (يكسره روشن ماندن چراغهاي جلو) يك مورد رويت شد | J133: عملکرد یکسره ادوات برقی | K133: NOK | L133: 1403/08/13 | M133: - | N133: - | O133: - | P133: - | Q133: قطعه دیود معیوب | R133: قطعه مورد تایید نبوده و در محصول استفاده گردیده | S133: دیود | T133: قطعه معیوب | U133: ایراد در مواد اولیه | V133: 1 | W133: IK01403980 | X133: - | Y133: 1403/08/13 | Z133: کاظمی پور | AA133: مواد اولیه | AB133: - | AC133: - | AD133: بسته شده | AE133: - | AF133: -
A134: 1 | B134: 203872 | C134: 1403/08/09 | D134: =MID(Table22[[#This Row],[تاريخ تاييد]],1,7) -> 1403/08 | E134: =MID(Table22[[#This Row],[تاريخ تاييد]],6,2) -> 08 | F134: =LEFT(Table22[[#This Row],[تاريخ تاييد]],4) -> 1403 | G134: =VLOOKUP(Table22[[#This Row],[شماره فني]],Sheet7!A:C,3,0) -> NOD | H134: =VLOOKUP(Table22[[#This Row],[شماره فني]],Sheet7!A:B,2,0) -> NBCM SOREN | I134: عدم عملكرد ريموت 2.روشن نشدن خودرو_طي بررسي هاي صورت گرفته منشأ ايراد مشاهده شده در سالن مونتاژ از نقص كيفي قطعه CBM مي باشد.ايراد به روئيت نماينده ساپكو رسيده است. | J134: عدم عملكرد قفل مركزي/ریموت | K134: - | L134: - | M134: - | N134: - | O134: - | P134: - | Q134: با توجه به اینکه قطعه دریافت نگردیده و ایراد مشابه در اخطار کیفی پیشین وجود داشته است،پاسخ حاضر بر اساس اقدامات قبلی ارائه شده است. | R134: - | S134: - | T134: عدم دریافت قطعه | U134: پاسخ با ایراد مشابه(عدم دریافت قطعه) | V134: 5 | W134: IK01750880 | X134: - | Y134: - | Z134: - | AA134: نامشخص | AB134: - | AC134: - | AD134: بسته شده | AE134: - | AF134: -
A135: 1 | B135: 203908 | C135: 1403/08/09 | D135: =MID(Table22[[#This Row],[تاريخ تاييد]],1,7) -> 1403/08 | E135: =MID(Table22[[#This Row],[تاريخ تاييد]],6,2) -> 08 | F135: =LEFT(Table22[[#This Row],[تاريخ تاييد]],4) -> 1403 | G135: =VLOOKUP(Table22[[#This Row],[شماره فني]],Sheet7!A:C,3,0) -> NOD | H135: =VLOOKUP(Table22[[#This Row],[شماره فني]],Sheet7!A:B,2,0) -> NBCM 207 | I135: ايراد عدم مونتاژ NBCM (عدم مونتاژNBCM برروي براكت شل بودن مهره ) هشت مورد رويت شد | J135: براکت | K135: - | L135: - | M135: - | N135: - | O135: - | P135: - | Q135: با توجه به اینکه قطعه دریافت نگردیده و ایراد مشابه در اخطار کیفی پیشین وجود داشته است،پاسخ حاضر بر اساس اقدامات قبلی ارائه شده است. | R135: - | S135: - | T135: عدم دریافت قطعه | U135: پاسخ با ایراد مشابه(عدم دریافت قطعه) | V135: 8 | W135: IK01596980 | X135: - | Y135: - | Z135: - | AA135: نامشخص | AB135: - | AC135: - | AD135: بسته شده | AE135: - | AF135: -
... A314: 1 | B314: 219134 | C314: 1404/06/24 | D314: =MID(Table22[[#This Row],[تاريخ تاييد]],1,7) -> 1404/06 | E314: =MID(Table22[[#This Row],[تاريخ تاييد]],6,2) -> 06 | F314: =LEFT(Table22[[#This Row],[تاريخ تاييد]],4) -> 1404 | G314: =VLOOKUP(Table22[[#This Row],[شماره فني]],Sheet7!A:C,3,0) -> جلو آمپر | H314: =VLOOKUP(Table22[[#This Row],[شماره فني]],Sheet7!A:B,2,0) -> جلو آمپر تارا دستی SBR | I314: ايرادي عملكردي جلوآمپر( عدم عملكرد عقربه دور موتور) رويت شد | J314: ایراد ظاهری | K314: - | L314: - | M314: - | N314: - | O314: - | P314: - | Q314: - | R314: - | S314: - | T314: عدم دریافت قطعه | U314: عدم دریافت قطعه | V314: 1 | W314: IK02623480 | X314: - | Y314: - | Z314: - | AA314: نامشخص | AB314: - | AC314: - | AD314: خاتمه يافته | AE314: - | AF314: -
A315: 1 | B315: 221361 | C315: 1404/08/01 | D315: =MID(Table22[[#This Row],[تاريخ تاييد]],1,7) -> 1404/08 | E315: =MID(Table22[[#This Row],[تاريخ تاييد]],6,2) -> 08 | F315: =LEFT(Table22[[#This Row],[تاريخ تاييد]],4) -> 1404 | G315: =VLOOKUP(Table22[[#This Row],[شماره فني]],Sheet7!A:C,3,0) -> جلو آمپر | H315: =VLOOKUP(Table22[[#This Row],[شماره فني]],Sheet7!A:B,2,0) -> جلو آمپرSOREN SBR | I315: ايراد پليسه گيري نامناسب لبه قاب مجموعه جلو آمپر مشاهده شده داخل بسته بندي | J315: کلید تریپ | K315: NOK | L315: 1404/09/11 | M315: - | N315: - | O315: - | P315: - | Q315: - | S315: میکروسوییچ | T315: قطعه معیوب | U315: ایراد در مواد اولیه | V315: 10 | W315: IK02623380 | X315: - | Y315: 1404/09/11 | Z315: کاظمی پور | AA315: مواد اولیه | AB315: - | AC315: - | AD315: خاتمه يافته | AE315: ارسال برای تامین کننده | AF315: -
A316: 1 | B316: 222434 | C316: 1404/08/20 | D316: =MID(Table22[[#This Row],[تاريخ تاييد]],1,7) -> 1404/08 | E316: =MID(Table22[[#This Row],[تاريخ تاييد]],6,2) -> 08 | F316: =LEFT(Table22[[#This Row],[تاريخ تاييد]],4) -> 1404 | G316: =VLOOKUP(Table22[[#This Row],[شماره فني]],Sheet7!A:C,3,0) -> کلید شیشه بالابر | H316: =VLOOKUP(Table22[[#This Row],[شماره فني]],Sheet7!A:B,2,0) -> کلید شیشه بالابر عقب چپ سورن SBR | I316: ايراد عدم عملكرد شيشه بالابر در عقب چپ به دليل انحراف پايه سوكت داخل پنل كليد شيشه بالابر بروز نموده است | J316: عملکرد نگینی(لوگو) | K316: NOK | L316: 1404/09/11 | M316: - | N316: - | O316: - | P316: - | Q316: - | R316: - | S316: LED | T316: مونتاژ اشتباه | U316: مونتاژ اشتباه قطعه | V316: 1 | W316: IK026729PB | X316: - | Y316: 1404/09/11 | Z316: کاظمی پور | AA316: تجهیزات | AB316: Chip Mounting خط 2 | AC316: سعید مهذب | AD316: خاتمه يافته | AE316: - | AF316: -
A317: 1 | B317: 215558 | C317: 1404/04/19 | D317: =MID(Table22[[#This Row],[تاريخ تاييد]],1,7) -> 1404/04 | E317: =MID(Table22[[#This Row],[تاريخ تاييد]],6,2) -> 04 | F317: =LEFT(Table22[[#This Row],[تاريخ تاييد]],4) -> 1404 | G317: =VLOOKUP(Table22[[#This Row],[شماره فني]],Sheet7!A:C,3,0) -> MFD | H317: =VLOOKUP(Table22[[#This Row],[شماره فني]],Sheet7!A:B,2,0) -> MFD RUNNA | I317: ايراد عملكرد نادرست نمايشگر ديجيتال بر روي داشبورد. | J317: عدم اعلام اخطار هشدار(بازر) | K317: NOK | L317: 1404/09/19 | M317: - | N317: - | O317: - | P317: - | Q317: - | R317: جدا شدن پایه بازر | S317: بازر | T317: قطعه معیوب | U317: ایراد در مواد اولیه | V317: 1 | W317: IK00473280 | X317: - | Y317: 1404/09/19 | Z317: کاظمی پور | AA317: مواد اولیه | AB317: - | AC317: - | AD317: خاتمه يافته | AE317: - | AF317: -
A318: 1 | B318: 219984 | C318: 1404/07/07 | D318: =MID(Table22[[#This Row],[تاريخ تاييد]],1,7) -> 1404/07 | E318: =MID(Table22[[#This Row],[تاريخ تاييد]],6,2) -> 07 | F318: =LEFT(Table22[[#This Row],[تاريخ تاييد]],4) -> 1404 | G318: =VLOOKUP(Table22[[#This Row],[شماره فني]],Sheet7!A:C,3,0) -> MFD | H318: =VLOOKUP(Table22[[#This Row],[شماره فني]],Sheet7!A:B,2,0) -> MFD RUNNA | I318: ايراد عدم نمايش نشانگر باز بودن درب جلو راست بر روي صفحه نمايشگر ديجيتالي بروز نموده است | J318: عدم عملكرد كامل | K318: NOK | L318: 1404/09/22 | M318: - | N318: - | O318: - | P318: - | Q318: - | R318: عدم قلع پذیری پایه کریستال | S318: کریستال | T318: قطعه معیوب | U318: ایراد در مواد اولیه | V318: 1 | W318: IK00473280 | X318: - | Y318: 1404/09/21 | Z318: کاظمی پور | AA318: مواد اولیه | AB318: - | AC318: - | AD318: خاتمه يافته | AE318: - | AF318: -
A319: 1 | B319: 216497 | C319: 1404/05/06 | D319: =MID(Table22[[#This Row],[تاريخ تاييد]],1,7) -> 1404/05 | E319: =MID(Table22[[#This Row],[تاريخ تاييد]],6,2) -> 05 | F319: =LEFT(Table22[[#This Row],[تاريخ تاييد]],4) -> 1404 | G319: =VLOOKUP(Table22[[#This Row],[شماره فني]],Sheet7!A:C,3,0) -> MFD | H319: =VLOOKUP(Table22[[#This Row],[شماره فني]],Sheet7!A:B,2,0) -> MFD RUNNA | I319: مطابق با اعلام نظر واحد آناليز-ايراد عدم عملكرد صفحه نمايشگر بالاي داشبورد و عدم عملكرد كولر مشخص گرديد به دليل ايراد كيفي مجموعه نمايشگر چند منظوره رانا ( با كد خطاي U100D عدم حضور نمايشگر چندگانه در شبكه -خطا و ايجاد اختلال در شبكه ).شايان ذكر است با توجه به شبكه بودن قطعه مذكور خرابي صفحه نمايشگر باعث عدم عملكرد كولر خودرو نيز گرديده است كه با تعويض قطعه هر دو ايراد رفع گرديد | J319: عدم عملكرد ادوات برقي خودرو | K319: OK | L319: 1404/09/19 | M319: - | N319: - | O319: - | P319: - | Q319: - | R319: - | S319: - | T319: درحال بررسی | U319: در حال بررسی | V319: 1 | W319: IK00473280 | X319: - | Y319: 1404/09/19 | Z319: کاظمی پور | AA319: نامشخص | AB319: - | AC319: - | AD319: خاتمه يافته | AE319: - | AF319: -
A320: 1 | B320: 216992 | C320: 1404/05/13 | D320: =MID(Table22[[#This Row],[تاريخ تاييد]],1,7) -> 1404/05 | E320: =MID(Table22[[#This Row],[تاريخ تاييد]],6,2) -> 05 | F320: =LEFT(Table22[[#This Row],[تاريخ تاييد]],4) -> 1404 | G320: =VLOOKUP(Table22[[#This Row],[شماره فني]],Sheet7!A:C,3,0) -> MFD | H320: =VLOOKUP(Table22[[#This Row],[شماره فني]],Sheet7!A:B,2,0) -> MFD RUNNA | I320: بدليل كم بودن تعداد كاراكتر هاي باركد رديابي ساعت روي داشبورد امكان ثبت آن وجود ندارد . | J320: عدم عملكرد ادوات برقي خودرو | K320: NOK | L320: 1404/09/29 | M320: - | N320: - | O320: - | P320: - | Q320: - | R320: نبود قلع بر روی پد بازر | S320: بازر | T320: نبود قلع بر روی پد | U320: در حال بررسی | V320: 10 | W320: IK00473280 | X320: - | Y320: 1404/09/29 | Z320: کاظمی پور | AA320: اپراتور | AB320: - | AC320: - | AD320: خاتمه يافته | AE320: - | AF320: -
A321: 1 | B321: 224052 | C321: 1404/09/19 | D321: =MID(Table22[[#This Row],[تاريخ تاييد]],1,7) -> 1404/09 | E321: =MID(Table22[[#This Row],[تاريخ تاييد]],6,2) -> 09 | F321: =LEFT(Table22[[#This Row],[تاريخ تاييد]],4) -> 1404 | G321: =VLOOKUP(Table22[[#This Row],[شماره فني]],Sheet7!A:C,3,0) -> NOD | H321: =VLOOKUP(Table22[[#This Row],[شماره فني]],Sheet7!A:B,2,0) -> SBM SOREN SBR | I321: ايراد عدم عملكرد لادري درب هاي عقب و صندوق و درب موتور به دليل معيوب بودن قطعه CBM (مجموعه جعبه الكترونيكي مالتي پلكس) بروز نموده است. | J321: ایراد در لیبل | K321: - | L321: - | M321: - | N321: - | O321: - | P321: - | Q321: - | R321: - | S321: - | T321: عدم دریافت قطعه | U321: عدم دریافت قطعه | V321: 1 | W321: IK02626980 | X321: - | Y321: - | Z321: - | AA321: نامشخص | AB321: - | AC321: - | AD321: خاتمه يافته | AE321: - | AF321: -
A322: 1 | B322: 215926 | C322: 1404/04/26 | D322: =MID(Table22[[#This Row],[تاريخ تاييد]],1,7) -> 1404/04 | E322: =MID(Table22[[#This Row],[تاريخ تاييد]],6,2) -> 04 | F322: =LEFT(Table22[[#This Row],[تاريخ تاييد]],4) -> 1404 | G322: =VLOOKUP(Table22[[#This Row],[شماره فني]],Sheet7!A:C,3,0) -> جلو آمپر | H322: =VLOOKUP(Table22[[#This Row],[شماره فني]],Sheet7!A:B,2,0) -> جلو آمپرSOREN TC 85 گانه | I322: ايراد عدم عملكرد صفحه ديجيتال (چراغ هاي هشدار ) بر روي جلو آمپر در خودرو سورن | J322: عدم عملكرد ادوات برقي خودرو | K322: - | L322: - | M322: - | N322: - | O322: - | P322: - | Q322: - | R322: - | S322: - | T322: عدم دریافت قطعه | U322: عدم دریافت قطعه | V322: 1 | W322: IK01033880 | X322: - | Y322: - | Z322: - | AA322: نامشخص | AB322: - | AC322: - | AD322: خاتمه يافته | AE322: - | AF322: -
B323: 221535 | C323: 1404/08/04 | D323: =MID(Table22[[#This Row],[تاريخ تاييد]],1,7) -> 1404/08 | E323: =MID(Table22[[#This Row],[تاريخ تاييد]],6,2) -> 08 | G323: =VLOOKUP(Table22[[#This Row],[شماره فني]],Sheet7!A:C,3,0) -> کلید شیشه بالابر | H323: =VLOOKUP(Table22[[#This Row],[شماره فني]],Sheet7!A:B,2,0) -> کلید شیشه بالابر عقب راست سورن SBR | I323: ايراد عدم قفل شدن سوكت پنل شيشه بالابر درب هاي عقب چپ و راست به دليل معيوب بودن مجموعه پنل بروز نموده است.ايراد به روئيت نماينده سازنده رسيده است. | V323: 1 | W323: IK026730PB | AD323: خاتمه يافته
B324: 215925 | C324: 1404/04/26 | D324: =MID(Table22[[#This Row],[تاريخ تاييد]],1,7) -> 1404/04 | E324: =MID(Table22[[#This Row],[تاريخ تاييد]],6,2) -> 04 | G324: =VLOOKUP(Table22[[#This Row],[شماره فني]],Sheet7!A:C,3,0) -> کلید شیشه بالابر | H324: =VLOOKUP(Table22[[#This Row],[شماره فني]],Sheet7!A:B,2,0) -> کلید شیشه بالابر جلو چپ سورن | I324: ايراد عدم عملكرد كليد قطع كن شيشه بالابرهاي درب هاي عقب بر روي پنل شيشه بالابر جلو چپ | V324: 1 | W324: IK016268PB | AD324: خاتمه يافته
B325: 217638 | C325: 1404/05/29 | D325: =MID(Table22[[#This Row],[تاريخ تاييد]],1,7) -> 1404/05 | E325: =MID(Table22[[#This Row],[تاريخ تاييد]],6,2) -> 05 | G325: =VLOOKUP(Table22[[#This Row],[شماره فني]],Sheet7!A:C,3,0) -> جلو آمپر | H325: =VLOOKUP(Table22[[#This Row],[شماره فني]],Sheet7!A:B,2,0) -> جلو آمپرSOREN TC 85 گانه | I325: ايراد صداي غيرعادي در هنگام حركت از جلو آمپر سورن به دليل لقي كليد تنظيم نور چراغ پشت آمپر. | V325: 4 | W325: IK01033880 | AD325: خاتمه يافته
B326: 216126 | C326: 1404/04/30 | D326: =MID(Table22[[#This Row],[تاريخ تاييد]],1,7) -> 1404/04 | E326: =MID(Table22[[#This Row],[تاريخ تاييد]],6,2) -> 04 | G326: =VLOOKUP(Table22[[#This Row],[شماره فني]],Sheet7!A:C,3,0) -> جلو آمپر | H326: =VLOOKUP(Table22[[#This Row],[شماره فني]],Sheet7!A:B,2,0) -> جلو آمپرSOREN TC 85 گانه | I326: ايراد صداي غير عادي از مجموعه جلو آمپر.ايراد به روئيت نماينده ساپكو رسيد | V326: 3 | W326: IK01033880 | AD326: خاتمه يافته
B327: 211086 | C327: 1404/01/16 | D327: =MID(Table22[[#This Row],[تاريخ تاييد]],1,7) -> 1404/01 | E327: =MID(Table22[[#This Row],[تاريخ تاييد]],6,2) -> 01 | G327: =VLOOKUP(Table22[[#This Row],[شماره فني]],Sheet7!A:C,3,0) -> جلو آمپر | H327: =VLOOKUP(Table22[[#This Row],[شماره فني]],Sheet7!A:B,2,0) -> جلو آمپرSOREN TC 85 گانه | I327: ايراد عدم عملكرد نمايشگر ديجيتال جلو امپر. | V327: 2 | W327: IK01033880 | AD327: خاتمه يافته
...

Sheet لیست قطعات برگشتی1403
A1: تعداد اخطار کیفی | B1: ردیف | C1: سريال اخطار | D1: تاريخ تاييد | E1: ماهیانه | F1: ماه | G1: سال | H1: محصولات | I1: شرح قطعه | J1: ایراد اعلام شده مشتری | K1: شرح ایراد | L1: تستر | M1: تاریخ تست | N1: تست خودرویی | O1: تاریخ تست خودرویی | P1: تست پیشنهادی | Q1: تاریخ تست پیشنهادی | R1: بررسی اول | S1: بررسی دوم | T1: بررسی سوم | U1: ریشه ایراد | V1: دلیل ایجاد ایراد | W1: تعداد قطعات معيوب | X1: شماره فني | Y1: بارکد محصول | Z1: تاریخ تحویل قطعه | AA1: تحویل گیرنده | AB1: 6M | AC1: تجهیزات | AD1: کد اپراتور | AE1: وضعیت | AF1: اقدام تعریف شده | AG1: مدارک
A2: 1 | B2: - | C2: 194290 | D2: 1403/01/16 | E2: =MID(Table2[[#This Row],[تاريخ تاييد]],1,7) -> 1403/01 | F2: =MID(Table2[[#This Row],[تاريخ تاييد]],6,2) -> 01 | G2: 1403 | H2: =VLOOKUP(Table2[[#This Row],[شماره فني]],Sheet7!A:C,3,0) -> NOD | I2: =VLOOKUP(Table2[[#This Row],[شماره فني]],Sheet7!A:B,2,0) -> NBCM DENA | J2: ايراد عملكردي nbcm (ليبل تكراري قطعه در تاريخ 1402/12/22 مونتاژ شده) رويت شد | K2: ایراد در لیبل | L2: - | M2: - | N2: - | O2: - | P2: - | Q2: - | R2: - | S2: - | T2: اشتباه اپراتور خط مشتری | U2: اشتباه اپراتور خط مشتری | V2: اشتباه اپراتور خط مشتری | W2: 1 | X2: IK01403980 | Y2: - | Z2: 1403/02/26 | AA2: کاظمی پور | AB2: روش | AC2: - | AD2: - | AE2: بسته شده | AF2: - | AG2: -
A3: 1 | B3: - | C3: 194407 | D3: 1403/01/19 | E3: =MID(Table2[[#This Row],[تاريخ تاييد]],1,7) -> 1403/01 | F3: =MID(Table2[[#This Row],[تاريخ تاييد]],6,2) -> 01 | G3: 1403 | H3: =VLOOKUP(Table2[[#This Row],[شماره فني]],Sheet7!A:C,3,0) -> جلو آمپر | I3: =VLOOKUP(Table2[[#This Row],[شماره فني]],Sheet7!A:B,2,0) -> جلو آمپرSOREN TC 85 گانه | J3: ايراد عدم جذب پشت امپر كه طبق بررسي هاي انجام گرفته ايراد فقط در سورس سازه پويش رويت مي گردد به طوريكه در پشت امپر كروز ايراد عدم جذب مشاهده نمي شود كه ايراد به رويت نماينده ساپكو اقاي كثيري رسيد(شكيب) | K3: ایراد ظاهری | L3: - | M3: - | N3: - | O3: - | P3: - | Q3: - | R3: ایراد ظاهری بود رویت شد | S3: - | T3: بزل | U3: ظاهری | V3: ایراد در مواد اولیه | W3: 50 | X3: IK01033880 | Y3: - | Z3: - | AA3: - | AB3: مواد اولیه | AC3: - | AD3: - | AE3: بسته شده | AF3: - | AG3: -
A4: 1 | B4: - | C4: 194427 | D4: 1403/01/19 | E4: =MID(Table2[[#This Row],[تاريخ تاييد]],1,7) -> 1403/01 | F4: =MID(Table2[[#This Row],[تاريخ تاييد]],6,2) -> 01 | G4: 1403 | H4: =VLOOKUP(Table2[[#This Row],[شماره فني]],Sheet7!A:C,3,0) -> جلو آمپر | I4: =VLOOKUP(Table2[[#This Row],[شماره فني]],Sheet7!A:B,2,0) -> جلو آمپر دنا اتوماتیک | J4: عطف به اسلايد2 فايل پيوست نتيجه گزارش دريافت شده از تستهاي دوره اي قطعه در اتيراك،عملكرد قطعه در بررسي پس از تست شوك حرارتي صحيح نميباشد. | K4: عدم عملكرد كامل | L4: - | M4: - | N4: - | O4: - | P4: - | Q4: - | R4: با توجه به اینکه قطعه دریافت نگردیده و ایراد مشابه در اخطار کیفی پیشین وجود داشته است،پاسخ حاضر بر اساس اقدامات قبلی ارائه شده است. | S4: - | T4: - | U4: عدم دریافت قطعه | V4: پاسخ با ایراد مشابه(عدم دریافت قطعه) | W4: 1 | X4: IK00929380 | Y4: - | Z4: - | AA4: - | AB4: نامشخص | AC4: - | AD4: - | AE4: بسته شده | AF4: - | AG4: -
A5: 1 | B5: - | C5: 194486 | D5: 1403/01/21 | E5: =MID(Table2[[#This Row],[تاريخ تاييد]],1,7) -> 1403/01 | F5: =MID(Table2[[#This Row],[تاريخ تاييد]],6,2) -> 01 | G5: 1403 | H5: =VLOOKUP(Table2[[#This Row],[شماره فني]],Sheet7!A:C,3,0) -> NOD | I5: =VLOOKUP(Table2[[#This Row],[شماره فني]],Sheet7!A:B,2,0) -> NBCM 207 | J5: ايراد عملكرد نادرست NBCM( مغايرت كانكتورنصب اشتباه)يك نمونه رويت شد | K5: کانکتور | L5: - | M5: - | N5: - | O5: - | P5: - | Q5: - | R5: با توجه به اینکه قطعه دریافت نگردیده و ایراد مشابه در اخطار کیفی پیشین وجود داشته است،پاسخ حاضر بر اساس اقدامات قبلی ارائه شده است. | S5: - | T5: - | U5: عدم دریافت قطعه | V5: پاسخ با ایراد مشابه(عدم دریافت قطعه) | W5: 1 | X5: IK01596980 | Y5: - | Z5: - | AA5: - | AB5: نامشخص | AC5: - | AD5: - | AE5: بسته شده | AF5: - | AG5: -
A6: 1 | B6: - | C6: 194549 | D6: 1403/01/21 | E6: =MID(Table2[[#This Row],[تاريخ تاييد]],1,7) -> 1403/01 | F6: =MID(Table2[[#This Row],[تاريخ تاييد]],6,2) -> 01 | G6: 1403 | H6: =VLOOKUP(Table2[[#This Row],[شماره فني]],Sheet7!A:C,3,0) -> جلو آمپر | I6: =VLOOKUP(Table2[[#This Row],[شماره فني]],Sheet7!A:B,2,0) -> جلو آمپر دنا اتوماتیک | J6: طي بررسي بعمل آمده ايراد عملكرد آمپر صفحه نمايشگر يك نمونه رويت گرديد | K6: LCD | L6: NOK | M6: 1403/04/11 | N6: - | O6: - | P6: - | Q6: - | R6: LCD معیوب | S6: تحویل مهندس رحمانی پور | T6: LCD | U6: قطعه معیوب | V6: ایراد در مواد اولیه | W6: 1 | X6: IK00929380 | Y6: RJAD2F10160269 | Z6: 1403/04/11 | AA6: کاظمی پور | AB6: مواد اولیه | AC6: - | AD6: - | AE6: بسته شده | AF6: - | AG6: -
A7: 1 | B7: - | C7: 194583 | D7: 1403/01/23 | E7: =MID(Table2[[#This Row],[تاريخ تاييد]],1,7) -> 1403/01 | F7: =MID(Table2[[#This Row],[تاريخ تاييد]],6,2) -> 01 | G7: 1403 | H7: =VLOOKUP(Table2[[#This Row],[شماره فني]],Sheet7!A:C,3,0) -> NOD | I7: =VLOOKUP(Table2[[#This Row],[شماره فني]],Sheet7!A:B,2,0) -> NBCM DENA | J7: ايرادعدم عملكرد NBCM( عدم عملكرد كامل)يك نمونه رويت شد | K7: عدم عملكرد ادوات برقي خودرو | L7: - | M7: - | N7: - | O7: - | P7: - | Q7: - | R7: با توجه به اینکه قطعه دریافت نگردیده و ایراد مشابه در اخطار کیفی پیشین وجود داشته است،پاسخ حاضر بر اساس اقدامات قبلی ارائه شده است. | S7: - | T7: - | U7: عدم دریافت قطعه | V7: پاسخ با ایراد مشابه(عدم دریافت قطعه) | W7: 1 | X7: IK01403980 | Y7: - | Z7: - | AA7: - | AB7: نامشخص | AC7: - | AD7: - | AE7: بسته شده | AF7: - | AG7: -
A8: 1 | B8: - | C8: 194584 | D8: 1403/01/23 | E8: =MID(Table2[[#This Row],[تاريخ تاييد]],1,7) -> 1403/01 | F8: =MID(Table2[[#This Row],[تاريخ تاييد]],6,2) -> 01 | G8: 1403 | H8: =VLOOKUP(Table2[[#This Row],[شماره فني]],Sheet7!A:C,3,0) -> جلو آمپر | I8: =VLOOKUP(Table2[[#This Row],[شماره فني]],Sheet7!A:B,2,0) -> جلو آمپر207 معمولی85 گانه | J8: ايرادليبل تكراري آمپرخودرو207يك نمونه رويت شد | K8: ایراد در لیبل | L8: - | M8: - | N8: - | O8: - | P8: - | Q8: - | R8: با توجه به اینکه قطعه دریافت نگردیده و ایراد مشابه در اخطار کیفی پیشین وجود داشته است،پاسخ حاضر بر اساس اقدامات قبلی ارائه شده است. | S8: - | T8: - | U8: عدم دریافت قطعه | V8: پاسخ با ایراد مشابه(عدم دریافت قطعه) | W8: 1 | X8: IK01033680 | Y8: - | Z8: - | AA8: - | AB8: نامشخص | AC8: - | AD8: - | AE8: بسته شده | AF8: - | AG8: -
A9: 1 | B9: - | C9: 194773 | D9: 1403/01/27 | E9: =MID(Table2[[#This Row],[تاريخ تاييد]],1,7) -> 1403/01 | F9: =MID(Table2[[#This Row],[تاريخ تاييد]],6,2) -> 01 | G9: 1403 | H9: =VLOOKUP(Table2[[#This Row],[شماره فني]],Sheet7!A:C,3,0) -> NOD | I9: =VLOOKUP(Table2[[#This Row],[شماره فني]],Sheet7!A:B,2,0) -> NBCM 207 | J9: ايرادعدم عملكرد NBCM( عدم عملكرد كامل اتصالي ادوات برقي )يك نمونه رويت شد | K9: عدم عملكرد ادوات برقي خودرو | L9: NOK | M9: 1403/02/26 | N9: - | O9: - | P9: - | Q9: - | R9: آثار فلکس بر روی pcb | S9: اتصالی اهمی | T9: برد | U9: اتصالی | V9: عدم عملکرد صحیح صفحه گرمایشی | W9: 1 | X9: IK01596980 | Y9: RU827F10162125 | Z9: 1403/02/26 | AA9: کاظمی پور | AB9: تجهیزات | AC9: وان قلع | AD9: - | AE9: بسته شده | AF9: - | AG9: -
A10: 1 | B10: - | C10: 194942 | D10: 1403/02/01 | E10: =MID(Table2[[#This Row],[تاريخ تاييد]],1,7) -> 1403/02 | F10: =MID(Table2[[#This Row],[تاريخ تاييد]],6,2) -> 02 | G10: 1403 | H10: =VLOOKUP(Table2[[#This Row],[شماره فني]],Sheet7!A:C,3,0) -> جلو آمپر | I10: =VLOOKUP(Table2[[#This Row],[شماره فني]],Sheet7!A:B,2,0) -> جلو آمپر دنا اتوماتیک | J10: ايرادعدم عملكردآمپرخودرو دنا(صفحه نمايشگر)يك نمونه رويت شد | K10: LCD | L10: OK | M10: 1403/02/26 | N10: NOK | O10: 1403/03/13 | P10: - | Q10: - | R10: LCD در تست خودرویی خاموش | S10: تحویل مهندس لهراسبی | T10: LCD | U10: قطعه معیوب | V10: ایراد در مواد اولیه | W10: 1 | X10: IK00929380 | Y10: RJAD2F10270105 | Z10: 1403/02/26 | AA10: کاظمی پور | AB10: مواد اولیه | AC10: - | AD10: - | AE10: بسته شده | AF10: - | AG10: -
A11: 1 | B11: - | C11: 194984 | D11: 1403/02/01 | E11: =MID(Table2[[#This Row],[تاريخ تاييد]],1,7) -> 1403/02 | F11: =MID(Table2[[#This Row],[تاريخ تاييد]],6,2) -> 02 | G11: 1403 | H11: =VLOOKUP(Table2[[#This Row],[شماره فني]],Sheet7!A:C,3,0) -> NOD | I11: =VLOOKUP(Table2[[#This Row],[شماره فني]],Sheet7!A:B,2,0) -> NBCM 207 | J11: ايراد عملكردي NBCM( عدم عملكرد سايد لمپ )يك نمونه رويت شد | K11: عدم عملكرد ادوات برقي خودرو | L11: NOK | M11: 1403/02/26 | N11: - | O11: - | P11: - | Q11: - | R11: - | S11: کمبود قلع پد تغذیه BTS | T11: IC BTS | U11: کمبود قلع | V11: مسدود بودن بخشی از سوراخ استنسیل و کامل نشدن مرحله چاپ قلع | W11: 1 | X11: IK01596980 | Y11: RU827F10282114 | Z11: 1403/02/26 | AA11: کاظمی پور | AB11: تجهیزات | AC11: SCREEN PRINTER | AD11: - | AE11: بسته شده | AF11: - | AG11: -
A12: 1 | B12: - | C12: 194985 | D12: 1403/02/01 | E12: =MID(Table2[[#This Row],[تاريخ تاييد]],1,7) -> 1403/02 | F12: =MID(Table2[[#This Row],[تاريخ تاييد]],6,2) -> 02 | G12: 1403 | H12: =VLOOKUP(Table2[[#This Row],[شماره فني]],Sheet7!A:C,3,0) -> جلو آمپر | I12: =VLOOKUP(Table2[[#This Row],[شماره فني]],Sheet7!A:B,2,0) -> جلو آمپر207 اتوماتیک85 گانه | J12: ايرادعدم عملكردآمپرخودرو207(عدم نمايش دماسنج)يك نمونه رويت شد | K12: عدم عملكرد ادوات برقي خودرو | L12: NOK | M12: 1403/02/26 | N12: - | O12: - | P12: - | Q12: - | R12: جدا شدن ترانزیستور | S12: آثار ضربه بر روی ترانزیستور مشهود است | T12: ترانزیستور | U12: کنده شدن قطعه | V12: بر اثر جابجایی | W12: 1 | X12: IK01917980 | Y12: RJA24F10140015 | Z12: 1403/02/26 | AA12: کاظمی پور | AB12: روش | AC12: - | AD12: - | AE12: بسته شده | AF12: - | AG12: -
A13: 1 | B13: - | C13: 194986 | D13: 1403/02/01 | E13: =MID(Table2[[#This Row],[تاريخ تاييد]],1,7) -> 1403/02 | F13: =MID(Table2[[#This Row],[تاريخ تاييد]],6,2) -> 02 | G13: 1403 | H13: =VLOOKUP(Table2[[#This Row],[شماره فني]],Sheet7!A:C,3,0) -> NOD | I13: =VLOOKUP(Table2[[#This Row],[شماره فني]],Sheet7!A:B,2,0) -> NBCM DENA | J13: ايراد مغايرت ليبل رديابي NBCM( ناخوانا بودن كه مربوط به توليد204 روز ) رويت شد | K13: ایراد در لیبل | L13: - | M13: - | N13: - | O13: - | P13: - | Q13: - | R13: - | S13: - | T13: محصول | U13: چاپ نامناسب لیبل | V13: ایراد در ریبون پرینتر | W13: 3 | X13: IK01403980 | Y13: - | Z13: - | AA13: - | AB13: تجهیزات | AC13: پرینتر | AD13: - | AE13: بسته شده | AF13: - | AG13: -
... A123: 1 | B123: - | C123: 203284 | D123: 1403/07/26 | E123: =MID(Table2[[#This Row],[تاريخ تاييد]],1,7) -> 1403/07 | F123: =MID(Table2[[#This Row],[تاريخ تاييد]],6,2) -> 07 | G123: 1403 | H123: =VLOOKUP(Table2[[#This Row],[شماره فني]],Sheet7!A:C,3,0) -> جلو آمپر | I123: =VLOOKUP(Table2[[#This Row],[شماره فني]],Sheet7!A:B,2,0) -> جلو آمپر دنا ST | J123: ايراد عملكردجلوآمپر(قطع و وصل پشت آمپر ) رويت شد. | K123: صداي اضافه و قطع و وصل پشت آمپر | L123: OK | M123: 1403/08/18 | N123: - | O123: - | P123: - | Q123: - | R123: شکسته بودن خازن ورودی رگلاتور | S123: خازن بر اثر جایگذاری نامناسب برد و یا جابجایی شکسته | T123: خازن | U123: قطعه شکسته | V123: بر اثر جابجایی | W123: 1 | X123: IK00843780 | Y123: - | Z123: 1403/08/13 | AA123: کاظمی پور | AB123: روش | AC123: - | AD123: - | AE123: بسته شده | AF123: - | AG123: -
A124: 1 | B124: - | C124: 203380 | D124: 1403/07/28 | E124: =MID(Table2[[#This Row],[تاريخ تاييد]],1,7) -> 1403/07 | F124: =MID(Table2[[#This Row],[تاريخ تاييد]],6,2) -> 07 | G124: =LEFT(Table2[[#This Row],[تاريخ تاييد]],4) -> 1403 | H124: =VLOOKUP(Table2[[#This Row],[شماره فني]],Sheet7!A:C,3,0) -> جلو آمپر | I124: =VLOOKUP(Table2[[#This Row],[شماره فني]],Sheet7!A:B,2,0) -> جلو آمپر207 معمولی85 گانه | J124: ايراد عملكردجلوآمپر(عدم عملكرد كامل ) رويت شد. | K124: عدم عملكرد كامل | L124: NOK | M124: 1403/08/18 | N124: - | O124: - | P124: - | Q124: - | R124: باتوجه به بررسی کارگروه ایراد در مقدار خازن کریستال میباشد که از 22پیکو به 10 پیکو کاهش یافت | S124: با شوک حرارتی قطعه Okشد | T124: کریستال | U124: قطعه معیوب | V124: ایراد در مواد اولیه | W124: 1 | X124: IK01033680 | Y124: - | Z124: 1403/08/13 | AA124: کاظمی پور | AB124: مواد اولیه | AC124: - | AD124: - | AE124: بسته شده | AF124: مقدار خازن کریستال از 22پیکو به 10 پیکو کاهش یافت | AG124: -
A125: 1 | B125: - | C125: 203385 | D125: 1403/07/28 | E125: =MID(Table2[[#This Row],[تاريخ تاييد]],1,7) -> 1403/07 | F125: =MID(Table2[[#This Row],[تاريخ تاييد]],6,2) -> 07 | G125: =LEFT(Table2[[#This Row],[تاريخ تاييد]],4) -> 1403 | H125: =VLOOKUP(Table2[[#This Row],[شماره فني]],Sheet7!A:C,3,0) -> NOD | I125: =VLOOKUP(Table2[[#This Row],[شماره فني]],Sheet7!A:B,2,0) -> NBCM TARA SAL | J125: اختلال عملكردي نودهاي مرتبط با NBCM طبق گزارش پسويت | K125: ایتراک | L125: - | M125: - | N125: - | O125: - | P125: - | Q125: - | R125: - | S125: - | T125: - | U125: عدم دریافت قطعه | V125: عدم دریافت قطعه | W125: 1 | X125: IK01843080 | Y125: - | Z125: - | AA125: - | AB125: نامشخص | AC125: - | AD125: - | AE125: عدم دریافت قطعه | AF125: - | AG125: -
A126: 1 | B126: - | C126: 203468 | D126: 1403/07/29 | E126: =MID(Table2[[#This Row],[تاريخ تاييد]],1,7) -> 1403/07 | F126: =MID(Table2[[#This Row],[تاريخ تاييد]],6,2) -> 07 | G126: =LEFT(Table2[[#This Row],[تاريخ تاييد]],4) -> 1403 | H126: =VLOOKUP(Table2[[#This Row],[شماره فني]],Sheet7!A:C,3,0) -> کلید شیشه بالابر | I126: =VLOOKUP(Table2[[#This Row],[شماره فني]],Sheet7!A:B,2,0) -> کلید شیشه بالابر عقب چپ سورن | J126: پليسه گيري نامطلوب كليد شيشه بالابر*****طرقي | K126: ایراد ظاهری | L126: - | M126: - | N126: - | O126: - | P126: - | Q126: - | R126: با توجه به اینکه قطعه دریافت نگردیده و ایراد مشابه در اخطار کیفی پیشین وجود داشته است،پاسخ حاضر بر اساس اقدامات قبلی ارائه شده است. | S126: - | T126: - | U126: عدم دریافت قطعه | V126: پاسخ با ایراد مشابه(عدم دریافت قطعه) | W126: 5 | X126: IK016270PB | Y126: - | Z126: - | AA126: - | AB126: نامشخص | AC126: - | AD126: - | AE126: بسته شده | AF126: - | AG126: -
A127: 1 | B127: - | C127: 203534 | D127: 1403/07/30 | E127: =MID(Table2[[#This Row],[تاريخ تاييد]],1,7) -> 1403/07 | F127: =MID(Table2[[#This Row],[تاريخ تاييد]],6,2) -> 07 | G127: =LEFT(Table2[[#This Row],[تاريخ تاييد]],4) -> 1403 | H127: =VLOOKUP(Table2[[#This Row],[شماره فني]],Sheet7!A:C,3,0) -> NOD | I127: =VLOOKUP(Table2[[#This Row],[شماره فني]],Sheet7!A:B,2,0) -> NBCM DENA | J127: ايراد عملكرد NBCM ( روشن نشدن خودرو استارت عملكرد ندارد) 2 مورد رويت شد | K127: روشن نشدن خودرو | L127: NOK | M127: 1403/08/13 | N127: - | O127: - | P127: - | Q127: - | R127: قطعه دیود معیوب | S127: قطعه مورد تایید نبوده و در محصول استفاده گردیده | T127: دیود | U127: قطعه معیوب | V127: ایراد در مواد اولیه | W127: 2 | X127: IK01403980 | Y127: - | Z127: 1403/08/13 | AA127: کاظمی پور | AB127: مواد اولیه | AC127: - | AD127: - | AE127: بسته شده | AF127: - | AG127: -
A128: 1 | B128: - | C128: 203553 | D128: 1403/07/30 | E128: =MID(Table2[[#This Row],[تاريخ تاييد]],1,7) -> 1403/07 | F128: =MID(Table2[[#This Row],[تاريخ تاييد]],6,2) -> 07 | G128: =LEFT(Table2[[#This Row],[تاريخ تاييد]],4) -> 1403 | H128: =VLOOKUP(Table2[[#This Row],[شماره فني]],Sheet7!A:C,3,0) -> کلید شیشه بالابر | I128: =VLOOKUP(Table2[[#This Row],[شماره فني]],Sheet7!A:B,2,0) -> کلید شیشه بالابر جلو چپ دنا | J128: عدم عملكرد كليد آينه تاشو در مجموعه كليد شيشه بالابر جلو چپ - خاكستري تيره- خودرو دنا؛ مرتبط با شركت سازه پويش | K128: عدم عملكرد ادوات برقي خودرو | L128: NOK | M128: 1403/08/13 | N128: - | O128: - | P128: - | Q128: - | R128: عدم اتصال صحيح پايه ic | S128: عدم اتصال صحیح پایه(IC) | T128: IC | U128: عدم اتصال مناسب | V128: استفاده از استنسيل شركت فراكلون | W128: 1 | X128: IK014085DG | Y128: - | Z128: 1403/08/09 | AA128: کاظمی پور | AB128: تجهیزات | AC128: SCREEN PRINTER | AD128: - | AE128: بسته شده | AF128: - | AG128: -
A129: 1 | B129: - | C129: 203619 | D129: 1403/08/01 | E129: =MID(Table2[[#This Row],[تاريخ تاييد]],1,7) -> 1403/08 | F129: =MID(Table2[[#This Row],[تاريخ تاييد]],6,2) -> 08 | G129: =LEFT(Table2[[#This Row],[تاريخ تاييد]],4) -> 1403 | H129: =VLOOKUP(Table2[[#This Row],[شماره فني]],Sheet7!A:C,3,0) -> کلید شیشه بالابر | I129: =VLOOKUP(Table2[[#This Row],[شماره فني]],Sheet7!A:B,2,0) -> کلید شیشه بالابر عقب راست سورن | J129: وجود پليسه و پليسه گيري نامناسب قاب كليد شيشه بالابر عقب راست | K129: ایراد ظاهری | L129: - | M129: - | N129: - | O129: - | P129: - | Q129: - | R129: با توجه به اینکه قطعه دریافت نگردیده و ایراد مشابه در اخطار کیفی پیشین وجود داشته است،پاسخ حاضر بر اساس اقدامات قبلی ارائه شده است. | S129: - | T129: - | U129: عدم دریافت قطعه | V129: پاسخ با ایراد مشابه(عدم دریافت قطعه) | W129: 3 | X129: IK016271PB | Y129: - | Z129: - | AA129: - | AB129: نامشخص | AC129: - | AD129: - | AE129: بسته شده | AF129: - | AG129: -
A130: 1 | B130: - | C130: 203749 | D130: 1403/08/05 | E130: =MID(Table2[[#This Row],[تاريخ تاييد]],1,7) -> 1403/08 | F130: =MID(Table2[[#This Row],[تاريخ تاييد]],6,2) -> 08 | G130: =LEFT(Table2[[#This Row],[تاريخ تاييد]],4) -> 1403 | H130: =VLOOKUP(Table2[[#This Row],[شماره فني]],Sheet7!A:C,3,0) -> جلو آمپر | I130: =VLOOKUP(Table2[[#This Row],[شماره فني]],Sheet7!A:B,2,0) -> جلو آمپر تارا اتوماتیک | J130: ايراد ظاهري جلوآمپر(كج بودن عقربه دور موتور ) رويت شد | K130: عقربه | L130: NOK | M130: 1403/09/07 | N130: - | O130: - | P130: - | Q130: - | R130: در زمان مونتاژ عقربه به دلیل عدم جایگیری صحیح در گیج با فشار لودسل عقربه کج و توسط بازرس دیده نشده | S130: انحنا در عقربه | T130: عقربه | U130: قطعه معیوب | V130: عدم جایگذاری مناسب عقربه در فیکسچر | W130: 1 | X130: IK01348180 | Y130: - | Z130: 1403/09/07 | AA130: کاظمی پور | AB130: اپراتور | AC130: - | AD130: تندرو،زندی | AE130: بسته شده | AF130: - | AG130: -
A131: 1 | B131: - | C131: 203785 | D131: 1403/08/05 | E131: =MID(Table2[[#This Row],[تاريخ تاييد]],1,7) -> 1403/08 | F131: =MID(Table2[[#This Row],[تاريخ تاييد]],6,2) -> 08 | G131: =LEFT(Table2[[#This Row],[تاريخ تاييد]],4) -> 1403 | H131: =VLOOKUP(Table2[[#This Row],[شماره فني]],Sheet7!A:C,3,0) -> کلید شیشه بالابر | I131: =VLOOKUP(Table2[[#This Row],[شماره فني]],Sheet7!A:B,2,0) -> کلید شیشه بالابر جلو چپ سورن | J131: ايراد عدم عملكرد كليد ها طبق بررسي مشخص گرديد ايراد مربوط به درفتگي خار پنل كليد بالابر كه ايراد به رويت نماينده سازنده اقاي راوندي رسيد | K131: ایراد ظاهری | L131: - | M131: - | N131: - | O131: - | P131: - | Q131: - | R131: کم بودن گوشت خار مجموعه کلید | S131: - | T131: قاب | U131: چفت نشدن خار | V131: ایراد در مواد اولیه | W131: 5 | X131: IK016268PB | Y131: - | Z131: 1403/09/07 | AA131: کاظمی پور | AB131: مواد اولیه | AC131: - | AD131: - | AE131: بسته شده | AF131: - | AG131: -
A132: 1 | B132: - | C132: 203803 | D132: 1403/08/06 | E132: =MID(Table2[[#This Row],[تاريخ تاييد]],1,7) -> 1403/08 | F132: =MID(Table2[[#This Row],[تاريخ تاييد]],6,2) -> 08 | G132: =LEFT(Table2[[#This Row],[تاريخ تاييد]],4) -> 1403 | H132: =VLOOKUP(Table2[[#This Row],[شماره فني]],Sheet7!A:C,3,0) -> NOD | I132: =VLOOKUP(Table2[[#This Row],[شماره فني]],Sheet7!A:B,2,0) -> NBCM TARA SAL | J132: ايراد عملكرد NBCM (خطاي مجازي .عدم پيكربنديNot OK) 1 مورد رويت شد | K132: خطاي مجازي | L132: - | M132: - | N132: - | O132: - | P132: - | Q132: - | R132: با توجه به اینکه قطعه دریافت نگردیده و ایراد مشابه در اخطار کیفی پیشین وجود داشته است،پاسخ حاضر بر اساس اقدامات قبلی ارائه شده است. | S132: - | T132: - | U132: عدم دریافت قطعه | V132: پاسخ با ایراد مشابه(عدم دریافت قطعه) | W132: 1 | X132: IK01843080 | Y132: - | Z132: - | AA132: - | AB132: نامشخص | AC132: - | AD132: - | AE132: بسته شده | AF132: - | AG132: -
A133: 1 | B133: - | C133: 203821 | D133: 1403/08/06 | E133: =MID(Table2[[#This Row],[تاريخ تاييد]],1,7) -> 1403/08 | F133: =MID(Table2[[#This Row],[تاريخ تاييد]],6,2) -> 08 | G133: =LEFT(Table2[[#This Row],[تاريخ تاييد]],4) -> 1403 | H133: =VLOOKUP(Table2[[#This Row],[شماره فني]],Sheet7!A:C,3,0) -> NOD | I133: =VLOOKUP(Table2[[#This Row],[شماره فني]],Sheet7!A:B,2,0) -> NBCM DENA | J133: ايراد عملكرد NBCM (يكسره روشن ماندن چراغهاي جلو) يك مورد رويت شد | K133: عملکرد یکسره ادوات برقی | L133: NOK | M133: 1403/08/13 | N133: - | O133: - | P133: - | Q133: - | R133: قطعه دیود معیوب | S133: قطعه مورد تایید نبوده و در محصول استفاده گردیده | T133: دیود | U133: قطعه معیوب | V133: ایراد در مواد اولیه | W133: 1 | X133: IK01403980 | Y133: - | Z133: 1403/08/13 | AA133: کاظمی پور | AB133: مواد اولیه | AC133: - | AD133: - | AE133: بسته شده | AF133: - | AG133: -
A134: 1 | B134: - | C134: 203872 | D134: 1403/08/09 | E134: =MID(Table2[[#This Row],[تاريخ تاييد]],1,7) -> 1403/08 | F134: =MID(Table2[[#This Row],[تاريخ تاييد]],6,2) -> 08 | G134: =LEFT(Table2[[#This Row],[تاريخ تاييد]],4) -> 1403 | H134: =VLOOKUP(Table2[[#This Row],[شماره فني]],Sheet7!A:C,3,0) -> NOD | I134: =VLOOKUP(Table2[[#This Row],[شماره فني]],Sheet7!A:B,2,0) -> NBCM SOREN | J134: عدم عملكرد ريموت 2.روشن نشدن خودرو_طي بررسي هاي صورت گرفته منشأ ايراد مشاهده شده در سالن مونتاژ از نقص كيفي قطعه CBM مي باشد.ايراد به روئيت نماينده ساپكو رسيده است. | K134: عدم عملكرد قفل مركزي/ریموت | L134: - | M134: - | N134: - | O134: - | P134: - | Q134: - | R134: با توجه به اینکه قطعه دریافت نگردیده و ایراد مشابه در اخطار کیفی پیشین وجود داشته است،پاسخ حاضر بر اساس اقدامات قبلی ارائه شده است. | S134: - | T134: - | U134: عدم دریافت قطعه | V134: پاسخ با ایراد مشابه(عدم دریافت قطعه) | W134: 5 | X134: IK01750880 | Y134: - | Z134: - | AA134: - | AB134: نامشخص | AC134: - | AD134: - | AE134: بسته شده | AF134: - | AG134: -
A135: 1 | B135: - | C135: 203908 | D135: 1403/08/09 | E135: =MID(Table2[[#This Row],[تاريخ تاييد]],1,7) -> 1403/08 | F135: =MID(Table2[[#This Row],[تاريخ تاييد]],6,2) -> 08 | G135: =LEFT(Table2[[#This Row],[تاريخ تاييد]],4) -> 1403 | H135: =VLOOKUP(Table2[[#This Row],[شماره فني]],Sheet7!A:C,3,0) -> NOD | I135: =VLOOKUP(Table2[[#This Row],[شماره فني]],Sheet7!A:B,2,0) -> NBCM 207 | J135: ايراد عدم مونتاژ NBCM (عدم مونتاژNBCM برروي براكت شل بودن مهره ) هشت مورد رويت شد | K135: براکت | L135: - | M135: - | N135: - | O135: - | P135: - | Q135: - | R135: با توجه به اینکه قطعه دریافت نگردیده و ایراد مشابه در اخطار کیفی پیشین وجود داشته است،پاسخ حاضر بر اساس اقدامات قبلی ارائه شده است. | S135: - | T135: - | U135: عدم دریافت قطعه | V135: پاسخ با ایراد مشابه(عدم دریافت قطعه) | W135: 8 | X135: IK01596980 | Y135: - | Z135: - | AA135: - | AB135: نامشخص | AC135: - | AD135: - | AE135: بسته شده | AF135: - | AG135: -
... A213: 1 | B213: - | C213: 210931 | D213: 1403/12/20 | E213: =MID(Table2[[#This Row],[تاريخ تاييد]],1,7) -> 1403/12 | F213: =MID(Table2[[#This Row],[تاريخ تاييد]],6,2) -> 12 | G213: =LEFT(Table2[[#This Row],[تاريخ تاييد]],4) -> 1403 | H213: =VLOOKUP(Table2[[#This Row],[شماره فني]],Sheet7!A:C,3,0) -> جلو آمپر | I213: =VLOOKUP(Table2[[#This Row],[شماره فني]],Sheet7!A:B,2,0) -> جلو آمپر تارا اتوماتیک | J213: ايراد عملكردي آمپر(عملكرد نگيني نور بالا و عملكردآمپر با تاخير )3 نمونه رويت شد | K213: عملکرد نگینی(لوگو) | L213: NOK | M213: 1404/01/24 | N213: - | O213: - | P213: - | Q213: - | R213: دیود مسیر باطری سوخته | S213: - | T213: دیود | U213: قطعه معیوب | V213: نامشخص | W213: 3 | X213: IK01348180 | Y213: - | Z213: 1404/01/24 | AA213: کاظمی پور | AB213: مواد اولیه | AC213: - | AD213: حسن پور | AE213: بسته شده | AF213: - | AG213: -
A214: 1 | B214: 0 | C214: 211052 | D214: 1403/12/22 | E214: =MID(Table2[[#This Row],[تاريخ تاييد]],1,7) -> 1403/12 | F214: =MID(Table2[[#This Row],[تاريخ تاييد]],6,2) -> 12 | G214: =LEFT(Table2[[#This Row],[تاريخ تاييد]],4) -> 1403 | H214: =VLOOKUP(Table2[[#This Row],[شماره فني]],Sheet7!A:C,3,0) -> NOD | I214: =VLOOKUP(Table2[[#This Row],[شماره فني]],Sheet7!A:B,2,0) -> NBCM TARA SAL | J214: ايراد عملكرد صداي آلارام هشدار يك مورد رويت گرديد | K214: عدم اعلام اخطار هشدار(بازر) | L214: NOK | M214: 1404/01/24 | N214: - | O214: - | P214: - | Q214: - | R214: بازر معیوب | S214: - | T214: بازر | U214: قطعه معیوب | V214: ایراد در مواد اولیه | W214: 1 | X214: IK01843080 | Y214: - | Z214: 1404/01/24 | AA214: کاظمی پور | AB214: مواد اولیه | AC214: - | AD214: - | AE214: بسته شده | AF214: - | AG214: -
A215: 1 | B215: - | C215: 211066 | D215: 1403/12/22 | E215: =MID(Table2[[#This Row],[تاريخ تاييد]],1,7) -> 1403/12 | F215: =MID(Table2[[#This Row],[تاريخ تاييد]],6,2) -> 12 | G215: =LEFT(Table2[[#This Row],[تاريخ تاييد]],4) -> 1403 | H215: =VLOOKUP(Table2[[#This Row],[شماره فني]],Sheet7!A:C,3,0) -> جلو آمپر | I215: =VLOOKUP(Table2[[#This Row],[شماره فني]],Sheet7!A:B,2,0) -> جلو آمپر تارا اتوماتیک | J215: ايراد عملكردي آمپر(نشتي نور نگيني راهنما چپ و راست )1 نمونه رويت شد | K215: عملکرد نگینی(لوگو) | L215: OK | M215: 1404/01/24 | N215: - | O215: - | P215: - | Q215: - | R215: LED استفاده شده در محصول جلو آمپر تارا دونوع می باشد که یکی پرنورتر می باشد | S215: - | T215: - | U215: موردی مشاهده نشد | V215: موردی مشاهده نشد | W215: 1 | X215: IK01348180 | Y215: - | Z215: 1404/01/24 | AA215: کاظمی پور | AB215: نامشخص | AC215: - | AD215: - | AE215: بسته شده | AF215: - | AG215: -
A216: 1 | B216: - | C216: 211086 | D216: 1404/01/16 | E216: =MID(Table2[[#This Row],[تاريخ تاييد]],1,7) -> 1404/01 | F216: =MID(Table2[[#This Row],[تاريخ تاييد]],6,2) -> 01 | G216: =LEFT(Table2[[#This Row],[تاريخ تاييد]],4) -> 1404 | H216: =VLOOKUP(Table2[[#This Row],[شماره فني]],Sheet7!A:C,3,0) -> جلو آمپر | I216: =VLOOKUP(Table2[[#This Row],[شماره فني]],Sheet7!A:B,2,0) -> جلو آمپرSOREN TC 85 گانه | J216: ايراد عدم عملكرد نمايشگر ديجيتال جلو امپر. | K216: LCD | L216: - | M216: - | N216: - | O216: - | P216: - | Q216: - | R216: با توجه به اینکه قطعه دریافت نگردیده و ایراد مشابه در اخطار کیفی پیشین وجود داشته است،پاسخ حاضر بر اساس اقدامات قبلی ارائه شده است. | S216: - | T216: - | U216: عدم دریافت قطعه | V216: پاسخ با ایراد مشابه(عدم دریافت قطعه) | W216: 2 | X216: IK01033880 | Y216: - | Z216: - | AA216: - | AB216: نامشخص | AC216: - | AD216: - | AE216: بسته شده | AF216: - | AG216: -
A217: 1 | B217: - | C217: 211232 | D217: 1403/12/25 | E217: =MID(Table2[[#This Row],[تاريخ تاييد]],1,7) -> 1403/12 | F217: =MID(Table2[[#This Row],[تاريخ تاييد]],6,2) -> 12 | G217: =LEFT(Table2[[#This Row],[تاريخ تاييد]],4) -> 1403 | H217: =VLOOKUP(Table2[[#This Row],[شماره فني]],Sheet7!A:C,3,0) -> NOD | I217: =VLOOKUP(Table2[[#This Row],[شماره فني]],Sheet7!A:B,2,0) -> NBCM 207 | J217: ايراد عملكردي Nbcm ( عدم تعريف ريموت قفل مركزي) رويت شد | K217: عدم عملكرد قفل مركزي/ریموت | L217: NOK | M217: 1404/01/24 | N217: - | O217: - | P217: - | Q217: - | R217: قطعه RF ماژول معیوبCY76 | S217: - | T217: ماژول | U217: قطعه معیوب | V217: ایراد در مواد اولیه | W217: 1 | X217: IK01596980 | Y217: - | Z217: - | AA217: - | AB217: مواد اولیه | AC217: - | AD217: - | AE217: بسته شده | AF217: - | AG217: -
A218: 1 | B218: - | C218: 211340 | D218: 1404/01/19 | E218: =MID(Table2[[#This Row],[تاريخ تاييد]],1,7) -> 1404/01 | F218: =MID(Table2[[#This Row],[تاريخ تاييد]],6,2) -> 01 | G218: =LEFT(Table2[[#This Row],[تاريخ تاييد]],4) -> 1404 | H218: =VLOOKUP(Table2[[#This Row],[شماره فني]],Sheet7!A:C,3,0) -> جلو آمپر | I218: =VLOOKUP(Table2[[#This Row],[شماره فني]],Sheet7!A:B,2,0) -> جلو آمپر207 اتوماتیک85 گانه | J218: ايراد عملكردي آمپر(عدم عملكرد كامل )يك نمونه رويت شد | K218: عدم عملكرد كامل | L218: NOK | M218: 1404/02/01 | N218: - | O218: - | P218: - | Q218: - | R218: شیفت IC1059 | S218: - | T218: IC1059 | U218: شیفت قطعه | V218: قطعه گذاری SMD | W218: 1 | X218: IK01917980 | Y218: - | Z218: 1404/02/01 | AA218: کاظمی پور | AB218: تجهیزات | AC218: MONNTER.SAMSUNG | AD218: - | AE218: بسته شده | AF218: - | AG218: -
